<?xml version='1.0'?>
<sdf version="1.9">
  <model name="traffic_bar">
    <link name="traffic_bar">
        <pose>0 0 0 0 0 0</pose>
        <inertial>
          <mass>0.1</mass>
          <inertia>
            <ixx>0.0001</ixx>
            <iyy>0.0001</iyy>
            <izz>0.0001</izz>
          </inertia>
        </inertial>
        <collision name="collision">
          <geometry>
            <box>
              <size>0.3 0.02 0.05</size>
            </box>
         </geometry>
        </collision>
        <visual name="visual">
        <geometry>
          <box>
            <size>0.3 0.02 0.05</size>
          </box>
        </geometry>
        <material>
          <ambient>1 1 1 1</ambient>
          <diffuse>1 1 1 1</diffuse>
          <specular>0.1 0.1 0.1 1</specular>
          <pbr>
            <metal>
              <albedo_map>model://turtlebot3_autorace_2020/traffic_bar/materials/textures/traffic_bar.png</albedo_map>
            </metal>
          </pbr>
        </material>
      </visual>
    </link>

    <joint name="bar_joint" type="revolute">
      <parent>world</parent>
      <child>traffic_bar</child>
      <pose>0.15 0 0 0 0 0</pose>
      <axis>
        <xyz>0 1 0</xyz>
        <limit>
          <lower>0</lower>
          <upper>1.5708</upper>
          <velocity>2</velocity> 
        </limit>
        <dynamics>
          <damping>0.1</damping>
        </dynamics>
      </axis>
    </joint>

<plugin filename="gz-sim-joint-position-controller-system"
            name="gz::sim::systems::JointPositionController">
      <joint_name>bar_joint</joint_name>
      <topic>/model/traffic_bar/joint/bar_joint/0/cmd_pos</topic>
      <p_gain>10.0</p_gain>
      <i_gain>0.0</i_gain>
      <d_gain>0.1</d_gain>
    </plugin>
  </model>
</sdf>